<?xml version="1.0" ?>
<robot name="LeArm">
    <link name="base_link">
        <visual>
            <geometry>
                <mesh filename="package://base.stl" />
            </geometry>
        </visual>       
        <inertial>
            <mass value="0.1" />
            <inertia ixx="0.03" iyy="0.03" izz="0.03" ixy="0.0" ixz="0.0" iyz="0.0" />
        </inertial>
    </link>
    <link name="shoulder_link">
        <visual>
            <geometry>
                <mesh filename="package://shoulder.stl" />
            </geometry>
        </visual>
       <inertial>
            <mass value="0.1" />
            <inertia ixx="0.03" iyy="0.03" izz="0.03" ixy="0.0" ixz="0.0" iyz="0.0" />
        </inertial>
    </link>
    <link name="humerus_link">
        <visual>
            <geometry>
                <mesh filename="package://humerus.stl" />
            </geometry>
        </visual>
        <inertial>
            <mass value="0.1" />
            <inertia ixx="0.03" iyy="0.03" izz="0.03" ixy="0.0" ixz="0.0" iyz="0.0" />
        </inertial>
    </link>
    <link name="forearm_link">
        <visual>
            <geometry>
                <mesh filename="package://forearm.stl" />
            </geometry>
        </visual>
        <inertial>
            <mass value="0.1" />
            <inertia ixx="0.03" iyy="0.03" izz="0.03" ixy="0.0" ixz="0.0" iyz="0.0" />
        </inertial>
    </link>
    <link name="wrist_link">
        <visual>
            <geometry>
                <mesh filename="package://wrist.stl" />
            </geometry>
        </visual>
        <inertial>
            <mass value="0.1" />
            <inertia ixx="0.03" iyy="0.03" izz="0.03" ixy="0.0" ixz="0.0" iyz="0.0" />
        </inertial>
    </link>
    <link name="hand_link">
        <visual>
            <geometry>
                <mesh filename="package://hand.stl" />
            </geometry>
        </visual>
        <inertial>
            <mass value="0.1" />
            <inertia ixx="0.03" iyy="0.03" izz="0.03" ixy="0.0" ixz="0.0" iyz="0.0" />
        </inertial>
    </link>
    <link name="grip_left_link">
        <visual>
            <geometry>
                <mesh filename="package://carpal-left.stl" />
            </geometry>
        </visual>
        <inertial>
            <mass value="0.1" />
            <inertia ixx="0.03" iyy="0.03" izz="0.03" ixy="0.0" ixz="0.0" iyz="0.0" />
        </inertial>
    </link>
    <link name="grip_right_link">
        <visual>
            <geometry>
                <mesh filename="package://carpal-right.stl" />
            </geometry>
        </visual>
        <inertial>
            <mass value="0.1" />
            <inertia ixx="0.03" iyy="0.03" izz="0.03" ixy="0.0" ixz="0.0" iyz="0.0" />
        </inertial>
    </link>
    <link name="tendon_left_link">
        <visual>
            <geometry>
                <mesh filename="package://tendon.stl" />
            </geometry>
        </visual>
        <inertial>
            <mass value="0.1" />
            <inertia ixx="0.03" iyy="0.03" izz="0.03" ixy="0.0" ixz="0.0" iyz="0.0" />
        </inertial>
    </link>
    <link name="tendon_right_link">
        <visual>
            <geometry>
                <mesh filename="package://tendon.stl" />
            </geometry>
        </visual>
        <inertial>
            <mass value="0.1" />
            <inertia ixx="0.03" iyy="0.03" izz="0.03" ixy="0.0" ixz="0.0" iyz="0.0" />
        </inertial>
    </link>
    <link name="finger_left_link">
        <visual>
            <geometry>
                <mesh filename="package://finger.stl" />
            </geometry>
        </visual>
        <inertial>
            <mass value="0.1" />
            <inertia ixx="0.03" iyy="0.03" izz="0.03" ixy="0.0" ixz="0.0" iyz="0.0" />
        </inertial>
    </link>
    <link name="finger_right_link">
        <visual>
            <origin rpy="0 0 3.14159" />
            <geometry>
                <mesh filename="package://finger.stl" />
            </geometry>
        </visual>
        <inertial>
            <mass value="0.1" />
            <inertia ixx="0.03" iyy="0.03" izz="0.03" ixy="0.0" ixz="0.0" iyz="0.0" />
        </inertial>
    </link>

    <joint name="shoulder_pan" type="revolute">
        <parent link="base_link" />
        <child link="shoulder_link" />
        <origin xyz="0 0 0.059" />
        <axis xyz="0 0 1" />
        <limit lower="-1.57" upper="1.57" effort="1000" velocity="0.5" />
    </joint>
    <joint name="shoulder_lift" type="revolute">
        <parent link="shoulder_link" />
        <child link="humerus_link" />
        <origin xyz="-0.010 0 0.028" />
        <axis xyz="0 1 0" />
        <limit lower="-1.57" upper="1.57" effort="1000" velocity="0.5" />
    </joint>
    <joint name="elbow" type="revolute">
        <parent link="humerus_link" />
        <child link="forearm_link" />
        <origin xyz="0 0 0.105" />
        <axis xyz="0 -1 0" />
        <limit lower="-1.57" upper="1.57" effort="1000" velocity="0.5" />
    </joint>
    <joint name="wrist_flex" type="revolute">
        <parent link="forearm_link" />
        <child link="wrist_link" />
        <origin xyz="0 0 0.090" />
        <axis xyz="0 -1 0" />
        <limit lower="-1.57" upper="1.57" effort="1000" velocity="0.5" />
    </joint>
    <joint name="wrist_roll" type="revolute">
        <parent link="wrist_link" />
        <child link="hand_link" />
        <origin xyz="0 0 0.060" />
        <axis xyz="0 0 1" />
        <limit lower="-1.57" upper="1.57" effort="1000" velocity="0.5" />
    </joint>
    <joint name="grip_left" type="revolute">
        <parent link="hand_link" />
        <child link="grip_left_link" />
        <origin xyz="0 +0.015 0.030" rpy="-1.57 0 0" />
        <axis xyz="-1 0 0" />
        <limit lower="-1.57" upper="0" effort="1000" velocity="0.5" />
    </joint>
    <joint name="grip_right" type="revolute">
        <parent link="hand_link" />
        <child link="grip_right_link" />
        <origin xyz="0 -0.015 0.030" rpy="1.57 0 0" />
        <axis xyz="-1 0 0" />
        <limit lower="0" upper="1.57" effort="1000" velocity="0.5" />
        <mimic joint="grip_left" multiplier="-1" />
    </joint>
    <joint name="tendon_left" type="revolute">
        <parent link="hand_link" />
        <child link="tendon_left_link" />
        <origin xyz="0 +0.005 0.050" rpy="-1.57 0 0" />
        <axis xyz="-1 0 0" />
        <limit lower="-1.57" upper="0" effort="1000" velocity="0.5" />
        <mimic joint="grip_left" />
    </joint>
    <joint name="tendon_right" type="revolute">
        <parent link="hand_link" />
        <child link="tendon_right_link" />
        <origin xyz="0 -0.005 0.050" rpy="1.57 0 0" />
        <axis xyz="-1 0 0" />
        <limit lower="0" upper="1.57" effort="1000" velocity="0.5" />
        <mimic joint="grip_left" multiplier="-1" />
    </joint>
    <joint name="finger_left" type="revolute">
        <parent link="grip_left_link" />
        <child link="finger_left_link" />
        <origin xyz="0 0 0.030" rpy="1.57 0 0" />
        <axis xyz="-1 0 0" />
        <limit lower="-1.57" upper="0" effort="1000" velocity="0.5" />
        <mimic joint="grip_left" multiplier="-1" />
    </joint>
    <joint name="finger_right" type="revolute">
        <parent link="grip_right_link" />
        <child link="finger_right_link" />
        <origin xyz="0 0 0.030" rpy="-1.57 0 0" />
        <axis xyz="-1 0 0" />
        <limit lower="0" upper="1.57" effort="1000" velocity="0.5" />
        <mimic joint="grip_left" />
    </joint>
</robot>